<?xml version="1.0" encoding="utf-8"?>
<!-- This URDF was automatically created by SolidWorks to URDF Exporter! Originally created by Stephen Brawner (brawner@gmail.com) 
     Commit Version: 1.6.0-1-g15f4949  Build Version: 1.6.7594.29634
     For more information, please see http://wiki.ros.org/sw_urdf_exporter -->
<robot
  name="twolegwheel">
  <link
    name="base_link">
    <inertial>
      <origin
        xyz="-0.013643004895774 7.93162980589686E-07 0.0859988058711454"
        rpy="0 0 0" />
      <mass
        value="3.10945390199589" />
      <inertia
        ixx="0.00934001308296876"
        ixy="-1.90416051881277E-09"
        ixz="1.49895631162341E-07"
        iyy="0.0217925945259764"
        iyz="-3.80295188180819E-08"
        izz="0.024080010541156" />
    </inertial>
    <visual>
      <origin
        xyz="0 0 0"
        rpy="0 0 0" />
      <geometry>
        <mesh
          filename="/home/oy/DRL/isaacgym/unitree_rl_gym/resources/robots/twolegwheel/meshes/base_link.STL" />
      </geometry>
      <material
        name="">
        <color
          rgba="0 0 0 1" />
      </material>
    </visual>
    <collision>
      <origin
        xyz="0 0 0"
        rpy="0 0 0" />
      <geometry>
        <mesh
          filename="/home/oy/DRL/isaacgym/unitree_rl_gym/resources/robots/twolegwheel/meshes/base_link.STL" />
      </geometry>
    </collision>
  </link>
  <link
    name="Left_Link1">
    <inertial>
      <origin
        xyz="0.00798255232984077 -4.50865902585395E-05 0.0367881420274613"
        rpy="0 0 0" />
      <mass
        value="0.238485739146011" />
      <inertia
        ixx="0.00016047963206388"
        ixy="-1.70377510394897E-08"
        ixz="2.36990442421365E-06"
        iyy="0.000162839075296289"
        iyz="8.40873201521928E-08"
        izz="0.000140875618411013" />
    </inertial>
    <visual>
      <origin
        xyz="0 0 0"
        rpy="0 0 0" />
      <geometry>
        <mesh
          filename="/home/oy/DRL/isaacgym/unitree_rl_gym/resources/robots/twolegwheel/meshes/Left_Link1.STL" />
      </geometry>
      <material
        name="">
        <color
          rgba="0.854901960784314 0.854901960784314 0.854901960784314 1" />
      </material>
    </visual>
    <collision>
      <origin
        xyz="0 0 0"
        rpy="0 0 0" />
      <geometry>
        <mesh
          filename="/home/oy/DRL/isaacgym/unitree_rl_gym/resources/robots/twolegwheel/meshes/Left_Link1.STL" />
      </geometry>
    </collision>
  </link>
  <joint
    name="Left_Joint1"
    type="revolute">
    <origin
      xyz="0.126001345954292 0 0.0577144013466578"
      rpy="3.14159265358979 -0.785398163397443 0" />
    <parent
      link="base_link" />
    <child
      link="Left_Link1" />
    <axis
      xyz="0 0 -1" />
    <limit
      lower="-3.14"
      upper="3.14"
      effort="9"
      velocity="4" />
  </joint>
  <link
    name="Left_Link2">
    <inertial>
      <origin
        xyz="-2.59212361961045E-05 -0.0478095316134824 -0.0104737983474144"
        rpy="0 0 0" />
      <mass
        value="0.124068775292257" />
      <inertia
        ixx="8.2152871682514E-05"
        ixy="-6.24494359433288E-09"
        ixz="-3.57216894518163E-08"
        iyy="3.44293185125146E-05"
        iyz="2.8318640578745E-06"
        izz="9.22034985201147E-05" />
    </inertial>
    <visual>
      <origin
        xyz="0 0 0"
        rpy="0 0 0" />
      <geometry>
        <mesh
          filename="/home/oy/DRL/isaacgym/unitree_rl_gym/resources/robots/twolegwheel/meshes/Left_Link2.STL" />
      </geometry>
      <material
        name="">
        <color
          rgba="1 1 1 1" />
      </material>
    </visual>
    <collision>
      <origin
        xyz="0 0 0"
        rpy="0 0 0" />
      <geometry>
        <mesh
          filename="/home/oy/DRL/isaacgym/unitree_rl_gym/resources/robots/twolegwheel/meshes/Left_Link2.STL" />
      </geometry>
    </collision>
  </link>
  <joint
    name="Left_Joint2"
    type="revolute">
    <origin
      xyz="0.04275 0 0.0410500000000001"
      rpy="-1.5707963267949 0 1.5707963267949" />
    <parent
      link="Left_Link1" />
    <child
      link="Left_Link2" />
    <axis
      xyz="0 0 -1" />
    <limit
      lower="-3.14"
      upper="3.14"
      effort="9"
      velocity="4" />
  </joint>
  <link
    name="Left_Link3">
    <inertial>
      <origin
        xyz="1.11543217521599E-05 -0.0160034117315547 -0.0377275570862977"
        rpy="0 0 0" />
      <mass
        value="0.154593855527533" />
      <inertia
        ixx="7.48360086999987E-05"
        ixy="8.92895374741486E-09"
        ixz="2.87062145894065E-08"
        iyy="8.38191871420754E-05"
        iyz="-8.9586850315822E-06"
        izz="6.20708624383725E-05" />
    </inertial>
    <visual>
      <origin
        xyz="0 0 0"
        rpy="0 0 0" />
      <geometry>
        <mesh
          filename="/home/oy/DRL/isaacgym/unitree_rl_gym/resources/robots/twolegwheel/meshes/Left_Link3.STL" />
      </geometry>
      <material
        name="">
        <color
          rgba="1 1 1 1" />
      </material>
    </visual>
    <collision>
      <origin
        xyz="0 0 0"
        rpy="0 0 0" />
      <geometry>
        <mesh
          filename="/home/oy/DRL/isaacgym/unitree_rl_gym/resources/robots/twolegwheel/meshes/Left_Link3.STL" />
      </geometry>
    </collision>
  </link>
  <joint
    name="Left_Joint3"
    type="revolute">
    <origin
      xyz="0 -0.0969 -0.0110500000000001"
      rpy="-1.5707963267949 0 0" />
    <parent
      link="Left_Link2" />
    <child
      link="Left_Link3" />
    <axis
      xyz="0 0 -1" />
    <limit
      lower="-3.14"
      upper="3.14"
      effort="1"
      velocity="15" />
  </joint>
  <link
    name="Left_Link4">
    <inertial>
      <origin
        xyz="5.79600776105739E-05 -0.0716988597958197 0.00570636373232694"
        rpy="0 0 0" />
      <mass
        value="0.145990900684867" />
      <inertia
        ixx="0.000190396621110576"
        ixy="7.81613638782877E-07"
        ixz="9.31454388057954E-08"
        iyy="3.6299339574335E-05"
        iyz="-1.86542623690102E-05"
        izz="0.00019317593775976" />
    </inertial>
    <visual>
      <origin
        xyz="0 0 0"
        rpy="0 0 0" />
      <geometry>
        <mesh
          filename="/home/oy/DRL/isaacgym/unitree_rl_gym/resources/robots/twolegwheel/meshes/Left_Link4.STL" />
      </geometry>
      <material
        name="">
        <color
          rgba="1 1 1 1" />
      </material>
    </visual>
    <collision>
      <origin
        xyz="0 0 0"
        rpy="0 0 0" />
      <geometry>
        <mesh
          filename="/home/oy/DRL/isaacgym/unitree_rl_gym/resources/robots/twolegwheel/meshes/Left_Link4.STL" />
      </geometry>
    </collision>
  </link>
  <joint
    name="Left_Joint4"
    type="revolute">
    <origin
      xyz="0 0.00799999999999998 -0.0409999999999999"
      rpy="1.5707963267949 0 -3.14159265358979" />
    <parent
      link="Left_Link3" />
    <child
      link="Left_Link4" />
    <axis
      xyz="0 0 -1" />
    <limit
      lower="-3.14"
      upper="3.14"
      effort="3"
      velocity="12" />
  </joint>
  <link
    name="Left_Link5">
    <inertial>
      <origin
        xyz="-5.30739440765447E-05 -0.00235248627116799 0.0301691000867451"
        rpy="0 0 0" />
      <mass
        value="0.096418478757106" />
      <inertia
        ixx="3.34601332651236E-05"
        ixy="-7.62053608668753E-09"
        ixz="1.99376169154024E-08"
        iyy="3.88654105004542E-05"
        iyz="3.78850515913553E-06"
        izz="2.75749493418457E-05" />
    </inertial>
    <visual>
      <origin
        xyz="0 0 0"
        rpy="0 0 0" />
      <geometry>
        <mesh
          filename="/home/oy/DRL/isaacgym/unitree_rl_gym/resources/robots/twolegwheel/meshes/Left_Link5.STL" />
      </geometry>
      <material
        name="">
        <color
          rgba="1 1 1 1" />
      </material>
    </visual>
    <collision>
      <origin
        xyz="0 0 0"
        rpy="0 0 0" />
      <geometry>
        <mesh
          filename="/home/oy/DRL/isaacgym/unitree_rl_gym/resources/robots/twolegwheel/meshes/Left_Link5.STL" />
      </geometry>
    </collision>
  </link>
  <joint
    name="Left_Joint5"
    type="revolute">
    <origin
      xyz="0 -0.1364 0.000999999999999945"
      rpy="1.57079632679489 0 0" />
    <parent
      link="Left_Link4" />
    <child
      link="Left_Link5" />
    <axis
      xyz="0 0 -1" />
    <limit
      lower="-3.14"
      upper="3.14"
      effort="1"
      velocity="15" />
  </joint>
  <link
    name="Left_Link6">
    <inertial>
      <origin
        xyz="1.26181413799689E-16 -0.0160077205818371 -0.0135000000000004"
        rpy="0 0 0" />
      <mass
        value="0.067417011826285" />
      <inertia
        ixx="3.50124967217308E-05"
        ixy="3.48673651139236E-20"
        ixz="-1.43749606913631E-21"
        iyy="1.4985800495038E-05"
        iyz="-1.05879118406787E-20"
        izz="4.4033848838378E-05" />
    </inertial>
    <visual>
      <origin
        xyz="0 0 0"
        rpy="0 0 0" />
      <geometry>
        <mesh
          filename="/home/oy/DRL/isaacgym/unitree_rl_gym/resources/robots/twolegwheel/meshes/Left_Link6.STL" />
      </geometry>
      <material
        name="">
        <color
          rgba="1 1 1 1" />
      </material>
    </visual>
    <collision>
      <origin
        xyz="0 0 0"
        rpy="0 0 0" />
      <geometry>
        <mesh
          filename="/home/oy/DRL/isaacgym/unitree_rl_gym/resources/robots/twolegwheel/meshes/Left_Link6.STL" />
      </geometry>
    </collision>
  </link>
  <joint
    name="Left_Joint6"
    type="revolute">
    <origin
      xyz="0 0.0174 0.036"
      rpy="-1.5708 0 3.1416" />
    <parent
      link="Left_Link5" />
    <child
      link="Left_Link6" />
    <axis
      xyz="0 0 -1" />
    <limit
      lower="-3.14"
      upper="3.14"
      effort="1"
      velocity="15" />
  </joint>
  <link
    name="Left_Wheel1">
    <inertial>
      <origin
        xyz="-3.46944695195361E-18 1.11022302462516E-16 0.0100000000000001"
        rpy="0 0 0" />
      <mass
        value="0.0517296128779225" />
      <inertia
        ixx="2.67967063887144E-05"
        ixy="-2.21145033190911E-21"
        ixz="-6.04424975907404E-21"
        iyy="2.67967063887144E-05"
        iyz="1.27054942088145E-20"
        izz="1.00310015763558E-05" />
    </inertial>
    <visual>
      <origin
        xyz="0 0 0"
        rpy="0 0 0" />
      <geometry>
        <mesh
          filename="/home/oy/DRL/isaacgym/unitree_rl_gym/resources/robots/twolegwheel/meshes/Left_Wheel1.STL" />
      </geometry>
      <material
        name="">
        <color
          rgba="1 1 1 1" />
      </material>
    </visual>
    <collision>
      <origin
        xyz="0 0 0"
        rpy="0 0 0" />
      <geometry>
        <mesh
          filename="/home/oy/DRL/isaacgym/unitree_rl_gym/resources/robots/twolegwheel/meshes/Left_Wheel1.STL" />
      </geometry>
    </collision>
  </link>
  <joint
    name="Left_Wheel1_Joint"
    type="fixed">
    <origin
      xyz="0.0225000000000002 -0.0425 -0.0235000000000004"
      rpy="0 0 0" />
    <parent
      link="Left_Link6" />
    <child
      link="Left_Wheel1" />
    <axis
      xyz="0 0 -1" />
  </joint>
  <link
    name="Left_Wheel2">
    <inertial>
      <origin
        xyz="1.38777878078145E-17 1.11022302462516E-16 0.0100000000000001"
        rpy="0 0 0" />
      <mass
        value="0.0517296128779226" />
      <inertia
        ixx="2.67967063887144E-05"
        ixy="6.153566380271E-22"
        ixz="-2.39970031490095E-21"
        iyy="2.67967063887144E-05"
        iyz="1.22819777351874E-20"
        izz="1.00310015763558E-05" />
    </inertial>
    <visual>
      <origin
        xyz="0 0 0"
        rpy="0 0 0" />
      <geometry>
        <mesh
          filename="/home/oy/DRL/isaacgym/unitree_rl_gym/resources/robots/twolegwheel/meshes/Left_Wheel2.STL" />
      </geometry>
      <material
        name="">
        <color
          rgba="1 1 1 1" />
      </material>
    </visual>
    <collision>
      <origin
        xyz="0 0 0"
        rpy="0 0 0" />
      <geometry>
        <mesh
          filename="/home/oy/DRL/isaacgym/unitree_rl_gym/resources/robots/twolegwheel/meshes/Left_Wheel2.STL" />
      </geometry>
    </collision>
  </link>
  <joint
    name="Left_Wheel2_Joint"
    type="fixed">
    <origin
      xyz="-0.0224999999999998 -0.0425000000000001 -0.0235000000000004"
      rpy="0 0 0" />
    <parent
      link="Left_Link6" />
    <child
      link="Left_Wheel2" />
    <axis
      xyz="0 0 -1" />
  </joint>
  <link
    name="Right_Link1">
    <inertial>
      <origin
        xyz="-0.00798255232481618 -3.17460933430335E-05 0.0367341196326673"
        rpy="0 0 0" />
      <mass
        value="0.238485739194803" />
      <inertia
        ixx="0.00016047963210501"
        ixy="9.86789665342891E-09"
        ixz="-2.35099818989148E-06"
        iyy="0.000162935769054922"
        iyz="-1.00610547185295E-07"
        izz="0.000140778924712756" />
    </inertial>
    <visual>
      <origin
        xyz="0 0 0"
        rpy="0 0 0" />
      <geometry>
        <mesh
          filename="/home/oy/DRL/isaacgym/unitree_rl_gym/resources/robots/twolegwheel/meshes/Right_Link1.STL" />
      </geometry>
      <material
        name="">
        <color
          rgba="1 1 1 1" />
      </material>
    </visual>
    <collision>
      <origin
        xyz="0 0 0"
        rpy="0 0 0" />
      <geometry>
        <mesh
          filename="/home/oy/DRL/isaacgym/unitree_rl_gym/resources/robots/twolegwheel/meshes/Right_Link1.STL" />
      </geometry>
    </collision>
  </link>
  <joint
    name="Right_Joint1"
    type="revolute">
    <origin
      xyz="-0.153287975927055 0 0.0577144013466578"
      rpy="3.14159265358979 0.785398163397443 0" />
    <parent
      link="base_link" />
    <child
      link="Right_Link1" />
    <axis
      xyz="0 0 -1" />
    <limit
      lower="-3.14"
      upper="3.14"
      effort="9"
      velocity="4" />
  </joint>
  <link
    name="Right_Link2">
    <inertial>
      <origin
        xyz="-0.0478095323053692 -2.11778235934747E-07 0.0108020452989008"
        rpy="0 0 0" />
      <mass
        value="0.124068777086543" />
      <inertia
        ixx="3.44293184238918E-05"
        ixy="-1.10599914290493E-08"
        ixz="-2.84637782291542E-06"
        iyy="8.21279974534663E-05"
        iyz="2.72559241935635E-09"
        izz="9.22283725821581E-05" />
    </inertial>
    <visual>
      <origin
        xyz="0 0 0"
        rpy="0 0 0" />
      <geometry>
        <mesh
          filename="/home/oy/DRL/isaacgym/unitree_rl_gym/resources/robots/twolegwheel/meshes/Right_Link2.STL" />
      </geometry>
      <material
        name="">
        <color
          rgba="1 1 1 1" />
      </material>
    </visual>
    <collision>
      <origin
        xyz="0 0 0"
        rpy="0 0 0" />
      <geometry>
        <mesh
          filename="/home/oy/DRL/isaacgym/unitree_rl_gym/resources/robots/twolegwheel/meshes/Right_Link2.STL" />
      </geometry>
    </collision>
  </link>
  <joint
    name="Right_Joint2"
    type="revolute">
    <origin
      xyz="-0.0425 0 0.0410499999999999"
      rpy="3.14159265358979 1.5707963267949 0" />
    <parent
      link="Right_Link1" />
    <child
      link="Right_Link2" />
    <axis
      xyz="0 0 -1" />
    <limit
      lower="-3.14"
      upper="3.14"
      effort="9"
      velocity="4" />
  </joint>
  <link
    name="Right_Link3">
    <inertial>
      <origin
        xyz="-2.54038085041023E-05 -0.0160034117009831 0.0377327521187761"
        rpy="0 0 0" />
      <mass
        value="0.15459385579605" />
      <inertia
        ixx="7.48514328485236E-05"
        ixy="-2.0019156254014E-08"
        ixz="2.2814227776546E-08"
        iyy="8.38191869508431E-05"
        iyz="8.96313524667185E-06"
        izz="6.2055438097884E-05" />
    </inertial>
    <visual>
      <origin
        xyz="0 0 0"
        rpy="0 0 0" />
      <geometry>
        <mesh
          filename="/home/oy/DRL/isaacgym/unitree_rl_gym/resources/robots/twolegwheel/meshes/Right_Link3.STL" />
      </geometry>
      <material
        name="">
        <color
          rgba="1 1 1 1" />
      </material>
    </visual>
    <collision>
      <origin
        xyz="0 0 0"
        rpy="0 0 0" />
      <geometry>
        <mesh
          filename="/home/oy/DRL/isaacgym/unitree_rl_gym/resources/robots/twolegwheel/meshes/Right_Link3.STL" />
      </geometry>
    </collision>
  </link>
  <joint
    name="Right_Joint3"
    type="revolute">
    <origin
      xyz="-0.0968999999999999 0 0.0113"
      rpy="1.5707963267949 0 -1.5707963267949" />
    <parent
      link="Right_Link2" />
    <child
      link="Right_Link3" />
    <axis
      xyz="0 0 -1" />
    <limit
      lower="-3.14"
      upper="3.14"
      effort="1"
      velocity="15" />
  </joint>
  <link
    name="Right_Link4">
    <inertial>
      <origin
        xyz="-8.40729039699672E-05 -0.071698860019824 -0.00566598542958532"
        rpy="0 0 0" />
      <mass
        value="0.145990900982084" />
      <inertia
        ixx="0.000190327954853196"
        ixy="-7.75883477899461E-07"
        ixz="1.23123324923911E-07"
        iyy="3.62993395258124E-05"
        iyz="1.86454574363625E-05"
        izz="0.000193244603901421" />
    </inertial>
    <visual>
      <origin
        xyz="0 0 0"
        rpy="0 0 0" />
      <geometry>
        <mesh
          filename="/home/oy/DRL/isaacgym/unitree_rl_gym/resources/robots/twolegwheel/meshes/Right_Link4.STL" />
      </geometry>
      <material
        name="">
        <color
          rgba="1 1 1 1" />
      </material>
    </visual>
    <collision>
      <origin
        xyz="0 0 0"
        rpy="0 0 0" />
      <geometry>
        <mesh
          filename="/home/oy/DRL/isaacgym/unitree_rl_gym/resources/robots/twolegwheel/meshes/Right_Link4.STL" />
      </geometry>
    </collision>
  </link>
  <joint
    name="Right_Joint4"
    type="revolute">
    <origin
      xyz="0 0.00799999999999992 0.0410000000000001"
      rpy="-1.5707963267949 0 -3.14159265358979" />
    <parent
      link="Right_Link3" />
    <child
      link="Right_Link4" />
    <axis
      xyz="0 0 -1" />
    <limit
      lower="-3.14"
      upper="3.14"
      effort="3"
      velocity="12" />
  </joint>
  <link
    name="Right_Link5">
    <inertial>
      <origin
        xyz="0.00235248632476898 -4.92389371896636E-05 0.0302096180304277"
        rpy="0 0 0" />
      <mass
        value="0.0964184778849924" />
      <inertia
        ixx="3.88654105033289E-05"
        ixy="7.05038274814246E-09"
        ixz="-3.79434968231281E-06"
        iyy="3.34498645747307E-05"
        iyz="-3.07755838105792E-08"
        izz="2.75852180331047E-05" />
    </inertial>
    <visual>
      <origin
        xyz="0 0 0"
        rpy="0 0 0" />
      <geometry>
        <mesh
          filename="/home/oy/DRL/isaacgym/unitree_rl_gym/resources/robots/twolegwheel/meshes/Right_Link5.STL" />
      </geometry>
      <material
        name="">
        <color
          rgba="1 1 1 1" />
      </material>
    </visual>
    <collision>
      <origin
        xyz="0 0 0"
        rpy="0 0 0" />
      <geometry>
        <mesh
          filename="/home/oy/DRL/isaacgym/unitree_rl_gym/resources/robots/twolegwheel/meshes/Right_Link5.STL" />
      </geometry>
    </collision>
  </link>
  <joint
    name="Right_Joint5"
    type="revolute">
    <origin
      xyz="0 -0.1364 -0.0010000000000002"
      rpy="1.5707963267949 -1.5707963267949 0" />
    <parent
      link="Right_Link4" />
    <child
      link="Right_Link5" />
    <axis
      xyz="0 0 -1" />
    <limit
      lower="-3.14"
      upper="3.14"
      effort="1"
      velocity="15" />
  </joint>
  <link
    name="Right_Link6">
    <inertial>
      <origin
        xyz="-0.0160077205818367 -1.26933380718931E-16 0.0135"
        rpy="0 0 0" />
      <mass
        value="0.067417011826285" />
      <inertia
        ixx="1.4985800495038E-05"
        ixy="-1.0341364158679E-20"
        ixz="-2.03287907341032E-20"
        iyy="3.50124967217308E-05"
        iyz="-1.03120296426692E-20"
        izz="4.4033848838378E-05" />
    </inertial>
    <visual>
      <origin
        xyz="0 0 0"
        rpy="0 0 0" />
      <geometry>
        <mesh
          filename="/home/oy/DRL/isaacgym/unitree_rl_gym/resources/robots/twolegwheel/meshes/Right_Link6.STL" />
      </geometry>
      <material
        name="">
        <color
          rgba="1 1 1 1" />
      </material>
    </visual>
    <collision>
      <origin
        xyz="0 0 0"
        rpy="0 0 0" />
      <geometry>
        <mesh
          filename="/home/oy/DRL/isaacgym/unitree_rl_gym/resources/robots/twolegwheel/meshes/Right_Link6.STL" />
      </geometry>
    </collision>
  </link>
  <joint
    name="Right_Joint6"
    type="revolute">
    <origin
      xyz="-0.0174 0 0.036"
      rpy="-1.7731 1.5708 1.4182" />
    <parent
      link="Right_Link5" />
    <child
      link="Right_Link6" />
    <axis
      xyz="0 0 -1" />
    <limit
      lower="-3.14"
      upper="3.14"
      effort="1"
      velocity="15" />
  </joint>
  <link
    name="Right_Wheel1">
    <inertial>
      <origin
        xyz="-3.46944695195361E-17 2.77555756156289E-16 -0.01"
        rpy="0 0 0" />
      <mass
        value="0.0517296128779226" />
      <inertia
        ixx="2.67967063887144E-05"
        ixy="1.05207658078635E-21"
        ixz="-1.17210704274547E-20"
        iyy="2.67967063887144E-05"
        iyz="3.81164826264435E-21"
        izz="1.00310015763558E-05" />
    </inertial>
    <visual>
      <origin
        xyz="0 0 0"
        rpy="0 0 0" />
      <geometry>
        <mesh
          filename="/home/oy/DRL/isaacgym/unitree_rl_gym/resources/robots/twolegwheel/meshes/Right_Wheel1.STL" />
      </geometry>
      <material
        name="">
        <color
          rgba="1 1 1 1" />
      </material>
    </visual>
    <collision>
      <origin
        xyz="0 0 0"
        rpy="0 0 0" />
      <geometry>
        <mesh
          filename="/home/oy/DRL/isaacgym/unitree_rl_gym/resources/robots/twolegwheel/meshes/Right_Wheel1.STL" />
      </geometry>
    </collision>
  </link>
  <joint
    name="Right_Wheel1_Joint"
    type="fixed">
    <origin
      xyz="-0.0424999999999999 0.0224999999999999 0.0235000000000001"
      rpy="0 0 1.5707963267949" />
    <parent
      link="Right_Link6" />
    <child
      link="Right_Wheel1" />
    <axis
      xyz="0 0 -1" />
  </joint>
  <link
    name="Right_Wheel2">
    <inertial>
      <origin
        xyz="0 5.55111512312578E-17 -0.00999999999999993"
        rpy="0 0 0" />
      <mass
        value="0.0517296128779226" />
      <inertia
        ixx="2.67967063887144E-05"
        ixy="-1.34286698588792E-21"
        ixz="-1.75249563957004E-20"
        iyy="2.67967063887144E-05"
        iyz="2.28698895758661E-20"
        izz="1.00310015763558E-05" />
    </inertial>
    <visual>
      <origin
        xyz="0 0 0"
        rpy="0 0 0" />
      <geometry>
        <mesh
          filename="/home/oy/DRL/isaacgym/unitree_rl_gym/resources/robots/twolegwheel/meshes/Right_Wheel2.STL" />
      </geometry>
      <material
        name="">
        <color
          rgba="1 1 1 1" />
      </material>
    </visual>
    <collision>
      <origin
        xyz="0 0 0"
        rpy="0 0 0" />
      <geometry>
        <mesh
          filename="/home/oy/DRL/isaacgym/unitree_rl_gym/resources/robots/twolegwheel/meshes/Right_Wheel2.STL" />
      </geometry>
    </collision>
  </link>
  <joint
    name="Right_Wheel2_Joint"
    type="fixed">
    <origin
      xyz="-0.0424999999999999 -0.0225000000000001 0.0235"
      rpy="0 0 1.5707963267949" />
    <parent
      link="Right_Link6" />
    <child
      link="Right_Wheel2" />
    <axis
      xyz="0 0 -1" />
  </joint>
</robot>